2020-01-27 13:02:26,145 ERROR: Exception on /explore [GET] [in /Users/nikhilnanda/Desktop/microblog/venv/lib/python3.6/site-packages/flask/app.py:1891]
Traceback (most recent call last):
  File "/Users/nikhilnanda/Desktop/microblog/venv/lib/python3.6/site-packages/flask/app.py", line 2446, in wsgi_app
    response = self.full_dispatch_request()
  File "/Users/nikhilnanda/Desktop/microblog/venv/lib/python3.6/site-packages/flask/app.py", line 1951, in full_dispatch_request
    rv = self.handle_user_exception(e)
  File "/Users/nikhilnanda/Desktop/microblog/venv/lib/python3.6/site-packages/flask/app.py", line 1820, in handle_user_exception
    reraise(exc_type, exc_value, tb)
  File "/Users/nikhilnanda/Desktop/microblog/venv/lib/python3.6/site-packages/flask/_compat.py", line 39, in reraise
    raise value
  File "/Users/nikhilnanda/Desktop/microblog/venv/lib/python3.6/site-packages/flask/app.py", line 1949, in full_dispatch_request
    rv = self.dispatch_request()
  File "/Users/nikhilnanda/Desktop/microblog/venv/lib/python3.6/site-packages/flask/app.py", line 1935, in dispatch_request
    return self.view_functions[rule.endpoint](**req.view_args)
  File "/Users/nikhilnanda/Desktop/flaskWeb-master/app/routes.py", line 205, in live
    return jsonify(content)
  File "/Users/nikhilnanda/Desktop/microblog/venv/lib/python3.6/site-packages/flask/json/__init__.py", line 370, in jsonify
    dumps(data, indent=indent, separators=separators) + "\n",
  File "/Users/nikhilnanda/Desktop/microblog/venv/lib/python3.6/site-packages/flask/json/__init__.py", line 211, in dumps
    rv = _json.dumps(obj, **kwargs)
  File "/Library/Frameworks/Python.framework/Versions/3.6/lib/python3.6/json/__init__.py", line 238, in dumps
    **kw).encode(obj)
  File "/Library/Frameworks/Python.framework/Versions/3.6/lib/python3.6/json/encoder.py", line 199, in encode
    chunks = self.iterencode(o, _one_shot=True)
  File "/Library/Frameworks/Python.framework/Versions/3.6/lib/python3.6/json/encoder.py", line 257, in iterencode
    return _iterencode(o, 0)
  File "/Users/nikhilnanda/Desktop/microblog/venv/lib/python3.6/site-packages/flask/json/__init__.py", line 100, in default
    return _json.JSONEncoder.default(self, o)
  File "/Library/Frameworks/Python.framework/Versions/3.6/lib/python3.6/json/encoder.py", line 180, in default
    o.__class__.__name__)
TypeError: Object of type 'bytes' is not JSON serializable
2020-01-27 13:03:20,939 INFO: Microblog startup [in /Users/nikhilnanda/Desktop/flaskWeb-master/app/__init__.py:49]
2020-01-27 13:59:19,504 INFO: Microblog startup [in /Users/nikhilnanda/Desktop/flaskWeb-master/app/__init__.py:49]
2020-01-27 13:59:33,237 ERROR: Exception on /explore [GET] [in /Users/nikhilnanda/Desktop/microblog/venv/lib/python3.6/site-packages/flask/app.py:1891]
Traceback (most recent call last):
  File "/Users/nikhilnanda/Desktop/microblog/venv/lib/python3.6/site-packages/flask/app.py", line 2446, in wsgi_app
    response = self.full_dispatch_request()
  File "/Users/nikhilnanda/Desktop/microblog/venv/lib/python3.6/site-packages/flask/app.py", line 1951, in full_dispatch_request
    rv = self.handle_user_exception(e)
  File "/Users/nikhilnanda/Desktop/microblog/venv/lib/python3.6/site-packages/flask/app.py", line 1820, in handle_user_exception
    reraise(exc_type, exc_value, tb)
  File "/Users/nikhilnanda/Desktop/microblog/venv/lib/python3.6/site-packages/flask/_compat.py", line 39, in reraise
    raise value
  File "/Users/nikhilnanda/Desktop/microblog/venv/lib/python3.6/site-packages/flask/app.py", line 1949, in full_dispatch_request
    rv = self.dispatch_request()
  File "/Users/nikhilnanda/Desktop/microblog/venv/lib/python3.6/site-packages/flask/app.py", line 1935, in dispatch_request
    return self.view_functions[rule.endpoint](**req.view_args)
  File "/Users/nikhilnanda/Desktop/flaskWeb-master/app/routes.py", line 211, in live
    return render_template('data.html', content=content["data"], numCol=numCol, numRow=numRow)
  File "/Users/nikhilnanda/Desktop/microblog/venv/lib/python3.6/site-packages/flask/templating.py", line 140, in render_template
    ctx.app,
  File "/Users/nikhilnanda/Desktop/microblog/venv/lib/python3.6/site-packages/flask/templating.py", line 120, in _render
    rv = template.render(context)
  File "/Users/nikhilnanda/Desktop/microblog/venv/lib/python3.6/site-packages/jinja2/asyncsupport.py", line 76, in render
    return original_render(self, *args, **kwargs)
  File "/Users/nikhilnanda/Desktop/microblog/venv/lib/python3.6/site-packages/jinja2/environment.py", line 1008, in render
    return self.environment.handle_exception(exc_info, True)
  File "/Users/nikhilnanda/Desktop/microblog/venv/lib/python3.6/site-packages/jinja2/environment.py", line 780, in handle_exception
    reraise(exc_type, exc_value, tb)
  File "/Users/nikhilnanda/Desktop/microblog/venv/lib/python3.6/site-packages/jinja2/_compat.py", line 37, in reraise
    raise value.with_traceback(tb)
  File "/Users/nikhilnanda/Desktop/flaskWeb-master/app/templates/data.html", line 1, in top-level template code
    {% extends "base.html" %}
  File "/Users/nikhilnanda/Desktop/flaskWeb-master/app/templates/base.html", line 1, in top-level template code
    {% extends 'bootstrap/base.html' %}
  File "/Users/nikhilnanda/Desktop/microblog/venv/lib/python3.6/site-packages/flask_bootstrap/templates/bootstrap/base.html", line 1, in top-level template code
    {% block doc -%}
  File "/Users/nikhilnanda/Desktop/microblog/venv/lib/python3.6/site-packages/flask_bootstrap/templates/bootstrap/base.html", line 4, in block "doc"
    {%- block html %}
  File "/Users/nikhilnanda/Desktop/microblog/venv/lib/python3.6/site-packages/flask_bootstrap/templates/bootstrap/base.html", line 20, in block "html"
    {% block body -%}
  File "/Users/nikhilnanda/Desktop/microblog/venv/lib/python3.6/site-packages/flask_bootstrap/templates/bootstrap/base.html", line 23, in block "body"
    {% block content -%}
  File "/Users/nikhilnanda/Desktop/flaskWeb-master/app/templates/base.html", line 49, in block "content"
    {% block app_content %}{% endblock %}
  File "/Users/nikhilnanda/Desktop/flaskWeb-master/app/templates/data.html", line 13, in block "app_content"
    {% for i in numRow %}
TypeError: 'int' object is not iterable
2020-01-27 14:00:29,605 INFO: Microblog startup [in /Users/nikhilnanda/Desktop/flaskWeb-master/app/__init__.py:49]
2020-01-27 14:04:13,703 INFO: Microblog startup [in /Users/nikhilnanda/Desktop/flaskWeb-master/app/__init__.py:49]
2020-01-27 14:10:47,502 INFO: Microblog startup [in /Users/nikhilnanda/Desktop/flaskWeb-master/app/__init__.py:49]
2020-01-27 14:11:17,852 INFO: Microblog startup [in /Users/nikhilnanda/Desktop/flaskWeb-master/app/__init__.py:49]
2020-01-27 14:15:00,795 INFO: Microblog startup [in /Users/nikhilnanda/Desktop/flaskWeb-master/app/__init__.py:49]
2020-01-27 14:15:07,064 ERROR: Exception on /explore [GET] [in /Users/nikhilnanda/Desktop/microblog/venv/lib/python3.6/site-packages/flask/app.py:1891]
Traceback (most recent call last):
  File "/Users/nikhilnanda/Desktop/microblog/venv/lib/python3.6/site-packages/flask/app.py", line 2446, in wsgi_app
    response = self.full_dispatch_request()
  File "/Users/nikhilnanda/Desktop/microblog/venv/lib/python3.6/site-packages/flask/app.py", line 1951, in full_dispatch_request
    rv = self.handle_user_exception(e)
  File "/Users/nikhilnanda/Desktop/microblog/venv/lib/python3.6/site-packages/flask/app.py", line 1820, in handle_user_exception
    reraise(exc_type, exc_value, tb)
  File "/Users/nikhilnanda/Desktop/microblog/venv/lib/python3.6/site-packages/flask/_compat.py", line 39, in reraise
    raise value
  File "/Users/nikhilnanda/Desktop/microblog/venv/lib/python3.6/site-packages/flask/app.py", line 1949, in full_dispatch_request
    rv = self.dispatch_request()
  File "/Users/nikhilnanda/Desktop/microblog/venv/lib/python3.6/site-packages/flask/app.py", line 1935, in dispatch_request
    return self.view_functions[rule.endpoint](**req.view_args)
  File "/Users/nikhilnanda/Desktop/flaskWeb-master/app/routes.py", line 208, in live
    numRow = len(content["data"])
KeyError: 'data'
2020-01-27 14:19:37,189 INFO: Microblog startup [in /Users/nikhilnanda/Desktop/flaskWeb-master/app/__init__.py:49]
2020-01-27 14:19:45,989 ERROR: Exception on /explore [GET] [in /Users/nikhilnanda/Desktop/microblog/venv/lib/python3.6/site-packages/flask/app.py:1891]
Traceback (most recent call last):
  File "/Users/nikhilnanda/Desktop/microblog/venv/lib/python3.6/site-packages/flask/app.py", line 2446, in wsgi_app
    response = self.full_dispatch_request()
  File "/Users/nikhilnanda/Desktop/microblog/venv/lib/python3.6/site-packages/flask/app.py", line 1951, in full_dispatch_request
    rv = self.handle_user_exception(e)
  File "/Users/nikhilnanda/Desktop/microblog/venv/lib/python3.6/site-packages/flask/app.py", line 1820, in handle_user_exception
    reraise(exc_type, exc_value, tb)
  File "/Users/nikhilnanda/Desktop/microblog/venv/lib/python3.6/site-packages/flask/_compat.py", line 39, in reraise
    raise value
  File "/Users/nikhilnanda/Desktop/microblog/venv/lib/python3.6/site-packages/flask/app.py", line 1949, in full_dispatch_request
    rv = self.dispatch_request()
  File "/Users/nikhilnanda/Desktop/microblog/venv/lib/python3.6/site-packages/flask/app.py", line 1935, in dispatch_request
    return self.view_functions[rule.endpoint](**req.view_args)
  File "/Users/nikhilnanda/Desktop/flaskWeb-master/app/routes.py", line 209, in live
    numCol = len(content["data"][0])
IndexError: list index out of range
2020-01-27 14:20:39,606 INFO: Microblog startup [in /Users/nikhilnanda/Desktop/flaskWeb-master/app/__init__.py:49]
2020-01-27 14:25:27,429 INFO: Microblog startup [in /Users/nikhilnanda/Desktop/flaskWeb-master/app/__init__.py:49]
2020-01-27 14:59:51,281 INFO: Microblog startup [in /Users/nikhilnanda/Desktop/flaskWeb-master/app/__init__.py:49]
2020-01-27 15:04:47,518 INFO: Microblog startup [in /Users/nikhilnanda/Desktop/flaskWeb-master/app/__init__.py:49]
2020-01-27 15:06:25,723 INFO: Microblog startup [in /Users/nikhilnanda/Desktop/flaskWeb-master/app/__init__.py:49]
