2020-01-28 13:28:42,018 ERROR: Exception on /edit_profile [GET] [in /Users/nikhilnanda/Desktop/microblog/venv/lib/python3.6/site-packages/flask/app.py:1891]
Traceback (most recent call last):
  File "/Users/nikhilnanda/Desktop/microblog/venv/lib/python3.6/site-packages/flask/app.py", line 2446, in wsgi_app
    response = self.full_dispatch_request()
  File "/Users/nikhilnanda/Desktop/microblog/venv/lib/python3.6/site-packages/flask/app.py", line 1951, in full_dispatch_request
    rv = self.handle_user_exception(e)
  File "/Users/nikhilnanda/Desktop/microblog/venv/lib/python3.6/site-packages/flask/app.py", line 1820, in handle_user_exception
    reraise(exc_type, exc_value, tb)
  File "/Users/nikhilnanda/Desktop/microblog/venv/lib/python3.6/site-packages/flask/_compat.py", line 39, in reraise
    raise value
  File "/Users/nikhilnanda/Desktop/microblog/venv/lib/python3.6/site-packages/flask/app.py", line 1949, in full_dispatch_request
    rv = self.dispatch_request()
  File "/Users/nikhilnanda/Desktop/microblog/venv/lib/python3.6/site-packages/flask/app.py", line 1935, in dispatch_request
    return self.view_functions[rule.endpoint](**req.view_args)
  File "/Users/nikhilnanda/Desktop/microblog/venv/lib/python3.6/site-packages/flask_login/utils.py", line 261, in decorated_view
    return func(*args, **kwargs)
  File "/Users/nikhilnanda/Desktop/flaskWeb-master/app/routes.py", line 161, in edit_profile
    return render_template('edit_profile.html', title='Edit Profile', form=form)
  File "/Users/nikhilnanda/Desktop/microblog/venv/lib/python3.6/site-packages/flask/templating.py", line 140, in render_template
    ctx.app,
  File "/Users/nikhilnanda/Desktop/microblog/venv/lib/python3.6/site-packages/flask/templating.py", line 120, in _render
    rv = template.render(context)
  File "/Users/nikhilnanda/Desktop/microblog/venv/lib/python3.6/site-packages/jinja2/asyncsupport.py", line 76, in render
    return original_render(self, *args, **kwargs)
  File "/Users/nikhilnanda/Desktop/microblog/venv/lib/python3.6/site-packages/jinja2/environment.py", line 1008, in render
    return self.environment.handle_exception(exc_info, True)
  File "/Users/nikhilnanda/Desktop/microblog/venv/lib/python3.6/site-packages/jinja2/environment.py", line 780, in handle_exception
    reraise(exc_type, exc_value, tb)
  File "/Users/nikhilnanda/Desktop/microblog/venv/lib/python3.6/site-packages/jinja2/_compat.py", line 37, in reraise
    raise value.with_traceback(tb)
  File "/Users/nikhilnanda/Desktop/flaskWeb-master/app/templates/edit_profile.html", line 1, in top-level template code
    {% extends "base.html" %}
  File "/Users/nikhilnanda/Desktop/flaskWeb-master/app/templates/base.html", line 1, in top-level template code
    {% extends 'bootstrap/base.html' %}
  File "/Users/nikhilnanda/Desktop/microblog/venv/lib/python3.6/site-packages/flask_bootstrap/templates/bootstrap/base.html", line 1, in top-level template code
    {% block doc -%}
  File "/Users/nikhilnanda/Desktop/microblog/venv/lib/python3.6/site-packages/flask_bootstrap/templates/bootstrap/base.html", line 4, in block "doc"
    {%- block html %}
  File "/Users/nikhilnanda/Desktop/microblog/venv/lib/python3.6/site-packages/flask_bootstrap/templates/bootstrap/base.html", line 20, in block "html"
    {% block body -%}
  File "/Users/nikhilnanda/Desktop/microblog/venv/lib/python3.6/site-packages/flask_bootstrap/templates/bootstrap/base.html", line 23, in block "body"
    {% block content -%}
  File "/Users/nikhilnanda/Desktop/flaskWeb-master/app/templates/base.html", line 52, in block "content"
    {% block app_content %}{% endblock %}
  File "/Users/nikhilnanda/Desktop/flaskWeb-master/app/templates/edit_profile.html", line 23, in block "app_content"
    {{ form.leagueId(size=32) }}<br>
TypeError: 'NoneType' object is not callable
2020-01-28 13:30:04,261 INFO: Microblog startup [in /Users/nikhilnanda/Desktop/flaskWeb-master/app/__init__.py:49]
2020-01-28 13:30:24,799 ERROR: Exception on /edit_profile [POST] [in /Users/nikhilnanda/Desktop/microblog/venv/lib/python3.6/site-packages/flask/app.py:1891]
Traceback (most recent call last):
  File "/Users/nikhilnanda/Desktop/microblog/venv/lib/python3.6/site-packages/sqlalchemy/engine/base.py", line 1246, in _execute_context
    cursor, statement, parameters, context
  File "/Users/nikhilnanda/Desktop/microblog/venv/lib/python3.6/site-packages/sqlalchemy/engine/default.py", line 581, in do_execute
    cursor.execute(statement, parameters)
sqlite3.InterfaceError: Error binding parameter 0 - probably unsupported type.

The above exception was the direct cause of the following exception:

Traceback (most recent call last):
  File "/Users/nikhilnanda/Desktop/microblog/venv/lib/python3.6/site-packages/flask/app.py", line 2446, in wsgi_app
    response = self.full_dispatch_request()
  File "/Users/nikhilnanda/Desktop/microblog/venv/lib/python3.6/site-packages/flask/app.py", line 1951, in full_dispatch_request
    rv = self.handle_user_exception(e)
  File "/Users/nikhilnanda/Desktop/microblog/venv/lib/python3.6/site-packages/flask/app.py", line 1820, in handle_user_exception
    reraise(exc_type, exc_value, tb)
  File "/Users/nikhilnanda/Desktop/microblog/venv/lib/python3.6/site-packages/flask/_compat.py", line 39, in reraise
    raise value
  File "/Users/nikhilnanda/Desktop/microblog/venv/lib/python3.6/site-packages/flask/app.py", line 1949, in full_dispatch_request
    rv = self.dispatch_request()
  File "/Users/nikhilnanda/Desktop/microblog/venv/lib/python3.6/site-packages/flask/app.py", line 1935, in dispatch_request
    return self.view_functions[rule.endpoint](**req.view_args)
  File "/Users/nikhilnanda/Desktop/microblog/venv/lib/python3.6/site-packages/flask_login/utils.py", line 261, in decorated_view
    return func(*args, **kwargs)
  File "/Users/nikhilnanda/Desktop/flaskWeb-master/app/routes.py", line 153, in edit_profile
    db.session.commit()
  File "/Users/nikhilnanda/Desktop/microblog/venv/lib/python3.6/site-packages/sqlalchemy/orm/scoping.py", line 162, in do
    return getattr(self.registry(), name)(*args, **kwargs)
  File "/Users/nikhilnanda/Desktop/microblog/venv/lib/python3.6/site-packages/sqlalchemy/orm/session.py", line 1036, in commit
    self.transaction.commit()
  File "/Users/nikhilnanda/Desktop/microblog/venv/lib/python3.6/site-packages/sqlalchemy/orm/session.py", line 503, in commit
    self._prepare_impl()
  File "/Users/nikhilnanda/Desktop/microblog/venv/lib/python3.6/site-packages/sqlalchemy/orm/session.py", line 482, in _prepare_impl
    self.session.flush()
  File "/Users/nikhilnanda/Desktop/microblog/venv/lib/python3.6/site-packages/sqlalchemy/orm/session.py", line 2479, in flush
    self._flush(objects)
  File "/Users/nikhilnanda/Desktop/microblog/venv/lib/python3.6/site-packages/sqlalchemy/orm/session.py", line 2617, in _flush
    transaction.rollback(_capture_exception=True)
  File "/Users/nikhilnanda/Desktop/microblog/venv/lib/python3.6/site-packages/sqlalchemy/util/langhelpers.py", line 68, in __exit__
    compat.reraise(exc_type, exc_value, exc_tb)
  File "/Users/nikhilnanda/Desktop/microblog/venv/lib/python3.6/site-packages/sqlalchemy/util/compat.py", line 153, in reraise
    raise value
  File "/Users/nikhilnanda/Desktop/microblog/venv/lib/python3.6/site-packages/sqlalchemy/orm/session.py", line 2577, in _flush
    flush_context.execute()
  File "/Users/nikhilnanda/Desktop/microblog/venv/lib/python3.6/site-packages/sqlalchemy/orm/unitofwork.py", line 422, in execute
    rec.execute(self)
  File "/Users/nikhilnanda/Desktop/microblog/venv/lib/python3.6/site-packages/sqlalchemy/orm/unitofwork.py", line 589, in execute
    uow,
  File "/Users/nikhilnanda/Desktop/microblog/venv/lib/python3.6/site-packages/sqlalchemy/orm/persistence.py", line 236, in save_obj
    update,
  File "/Users/nikhilnanda/Desktop/microblog/venv/lib/python3.6/site-packages/sqlalchemy/orm/persistence.py", line 996, in _emit_update_statements
    statement, multiparams
  File "/Users/nikhilnanda/Desktop/microblog/venv/lib/python3.6/site-packages/sqlalchemy/engine/base.py", line 982, in execute
    return meth(self, multiparams, params)
  File "/Users/nikhilnanda/Desktop/microblog/venv/lib/python3.6/site-packages/sqlalchemy/sql/elements.py", line 287, in _execute_on_connection
    return connection._execute_clauseelement(self, multiparams, params)
  File "/Users/nikhilnanda/Desktop/microblog/venv/lib/python3.6/site-packages/sqlalchemy/engine/base.py", line 1101, in _execute_clauseelement
    distilled_params,
  File "/Users/nikhilnanda/Desktop/microblog/venv/lib/python3.6/site-packages/sqlalchemy/engine/base.py", line 1250, in _execute_context
    e, statement, parameters, cursor, context
  File "/Users/nikhilnanda/Desktop/microblog/venv/lib/python3.6/site-packages/sqlalchemy/engine/base.py", line 1476, in _handle_dbapi_exception
    util.raise_from_cause(sqlalchemy_exception, exc_info)
  File "/Users/nikhilnanda/Desktop/microblog/venv/lib/python3.6/site-packages/sqlalchemy/util/compat.py", line 398, in raise_from_cause
    reraise(type(exception), exception, tb=exc_tb, cause=cause)
  File "/Users/nikhilnanda/Desktop/microblog/venv/lib/python3.6/site-packages/sqlalchemy/util/compat.py", line 152, in reraise
    raise value.with_traceback(tb)
  File "/Users/nikhilnanda/Desktop/microblog/venv/lib/python3.6/site-packages/sqlalchemy/engine/base.py", line 1246, in _execute_context
    cursor, statement, parameters, context
  File "/Users/nikhilnanda/Desktop/microblog/venv/lib/python3.6/site-packages/sqlalchemy/engine/default.py", line 581, in do_execute
    cursor.execute(statement, parameters)
sqlalchemy.exc.InterfaceError: (sqlite3.InterfaceError) Error binding parameter 0 - probably unsupported type.
[SQL: UPDATE user SET "leagueId"=?, "teamId"=? WHERE user.id = ?]
[parameters: (<wtforms.fields.core.StringField object at 0x110adfa90>, <wtforms.fields.core.StringField object at 0x110adfe80>, 1)]
(Background on this error at: http://sqlalche.me/e/rvf5)
2020-01-28 13:33:06,808 INFO: Microblog startup [in /Users/nikhilnanda/Desktop/flaskWeb-master/app/__init__.py:49]
